2020-06-22 14:02:49,889 ERROR: Exception on /reset_password_request [POST] [in /Users/ilja/.virtualenvs/flask-megatut-FibpGiLO/lib/python3.7/site-packages/flask/app.py:1892]
Traceback (most recent call last):
  File "/Users/ilja/.virtualenvs/flask-megatut-FibpGiLO/lib/python3.7/site-packages/flask/app.py", line 2447, in wsgi_app
    response = self.full_dispatch_request()
  File "/Users/ilja/.virtualenvs/flask-megatut-FibpGiLO/lib/python3.7/site-packages/flask/app.py", line 1952, in full_dispatch_request
    rv = self.handle_user_exception(e)
  File "/Users/ilja/.virtualenvs/flask-megatut-FibpGiLO/lib/python3.7/site-packages/flask/app.py", line 1821, in handle_user_exception
    reraise(exc_type, exc_value, tb)
  File "/Users/ilja/.virtualenvs/flask-megatut-FibpGiLO/lib/python3.7/site-packages/flask/_compat.py", line 39, in reraise
    raise value
  File "/Users/ilja/.virtualenvs/flask-megatut-FibpGiLO/lib/python3.7/site-packages/flask/app.py", line 1950, in full_dispatch_request
    rv = self.dispatch_request()
  File "/Users/ilja/.virtualenvs/flask-megatut-FibpGiLO/lib/python3.7/site-packages/flask/app.py", line 1936, in dispatch_request
    return self.view_functions[rule.endpoint](**req.view_args)
  File "/Users/ilja/Dropbox/flask-megatut/app/routes.py", line 235, in reset_password_request
    return redirect(url_for('login'))
  File "/Users/ilja/.virtualenvs/flask-megatut-FibpGiLO/lib/python3.7/site-packages/flask/helpers.py", line 370, in url_for
    return appctx.app.handle_url_build_error(error, endpoint, values)
  File "/Users/ilja/.virtualenvs/flask-megatut-FibpGiLO/lib/python3.7/site-packages/flask/app.py", line 2216, in handle_url_build_error
    reraise(exc_type, exc_value, tb)
  File "/Users/ilja/.virtualenvs/flask-megatut-FibpGiLO/lib/python3.7/site-packages/flask/_compat.py", line 39, in reraise
    raise value
  File "/Users/ilja/.virtualenvs/flask-megatut-FibpGiLO/lib/python3.7/site-packages/flask/helpers.py", line 358, in url_for
    endpoint, values, method=method, force_external=external
  File "/Users/ilja/.virtualenvs/flask-megatut-FibpGiLO/lib/python3.7/site-packages/werkzeug/routing.py", line 2179, in build
    raise BuildError(endpoint, values, method, self)
werkzeug.routing.BuildError: Could not build url for endpoint 'login'. Did you mean 'log1n' instead?
2020-06-22 14:03:14,847 INFO: Microblog startup [in /Users/ilja/Dropbox/flask-megatut/app/__init__.py:76]
2020-06-22 14:22:50,746 INFO: Microblog startup [in /Users/ilja/Dropbox/flask-megatut/app/__init__.py:76]
2020-06-23 10:09:20,894 INFO: Microblog startup [in /Users/ilja/Dropbox/flask-megatut/app/__init__.py:76]
2020-06-23 10:10:32,899 ERROR: Exception on /view_db [GET] [in /Users/ilja/.virtualenvs/flask-megatut-FibpGiLO/lib/python3.7/site-packages/flask/app.py:1892]
Traceback (most recent call last):
  File "/Users/ilja/.virtualenvs/flask-megatut-FibpGiLO/lib/python3.7/site-packages/flask/app.py", line 2447, in wsgi_app
    response = self.full_dispatch_request()
  File "/Users/ilja/.virtualenvs/flask-megatut-FibpGiLO/lib/python3.7/site-packages/flask/app.py", line 1953, in full_dispatch_request
    return self.finalize_request(rv)
  File "/Users/ilja/.virtualenvs/flask-megatut-FibpGiLO/lib/python3.7/site-packages/flask/app.py", line 1968, in finalize_request
    response = self.make_response(rv)
  File "/Users/ilja/.virtualenvs/flask-megatut-FibpGiLO/lib/python3.7/site-packages/flask/app.py", line 2098, in make_response
    "The view function did not return a valid response. The"
TypeError: The view function did not return a valid response. The function either returned None or ended without a return statement.
2020-06-23 10:11:23,687 INFO: Microblog startup [in /Users/ilja/Dropbox/flask-megatut/app/__init__.py:76]
2020-06-23 10:13:05,865 INFO: Microblog startup [in /Users/ilja/Dropbox/flask-megatut/app/__init__.py:76]
2020-06-23 10:13:28,395 INFO: Microblog startup [in /Users/ilja/Dropbox/flask-megatut/app/__init__.py:76]
2020-06-23 10:15:40,788 INFO: Microblog startup [in /Users/ilja/Dropbox/flask-megatut/app/__init__.py:76]
2020-06-23 10:15:46,395 ERROR: Exception on /view_db [GET] [in /Users/ilja/.virtualenvs/flask-megatut-FibpGiLO/lib/python3.7/site-packages/flask/app.py:1892]
Traceback (most recent call last):
  File "/Users/ilja/.virtualenvs/flask-megatut-FibpGiLO/lib/python3.7/site-packages/flask/app.py", line 2447, in wsgi_app
    response = self.full_dispatch_request()
  File "/Users/ilja/.virtualenvs/flask-megatut-FibpGiLO/lib/python3.7/site-packages/flask/app.py", line 1952, in full_dispatch_request
    rv = self.handle_user_exception(e)
  File "/Users/ilja/.virtualenvs/flask-megatut-FibpGiLO/lib/python3.7/site-packages/flask/app.py", line 1821, in handle_user_exception
    reraise(exc_type, exc_value, tb)
  File "/Users/ilja/.virtualenvs/flask-megatut-FibpGiLO/lib/python3.7/site-packages/flask/_compat.py", line 39, in reraise
    raise value
  File "/Users/ilja/.virtualenvs/flask-megatut-FibpGiLO/lib/python3.7/site-packages/flask/app.py", line 1950, in full_dispatch_request
    rv = self.dispatch_request()
  File "/Users/ilja/.virtualenvs/flask-megatut-FibpGiLO/lib/python3.7/site-packages/flask/app.py", line 1936, in dispatch_request
    return self.view_functions[rule.endpoint](**req.view_args)
  File "/Users/ilja/.virtualenvs/flask-megatut-FibpGiLO/lib/python3.7/site-packages/flask_login/utils.py", line 272, in decorated_view
    return func(*args, **kwargs)
  File "/Users/ilja/Dropbox/flask-megatut/app/routes.py", line 259, in view_db
    return render_template('view_db.html')
  File "/Users/ilja/.virtualenvs/flask-megatut-FibpGiLO/lib/python3.7/site-packages/flask/templating.py", line 140, in render_template
    ctx.app,
  File "/Users/ilja/.virtualenvs/flask-megatut-FibpGiLO/lib/python3.7/site-packages/flask/templating.py", line 120, in _render
    rv = template.render(context)
  File "/Users/ilja/.virtualenvs/flask-megatut-FibpGiLO/lib/python3.7/site-packages/jinja2/environment.py", line 1090, in render
    self.environment.handle_exception()
  File "/Users/ilja/.virtualenvs/flask-megatut-FibpGiLO/lib/python3.7/site-packages/jinja2/environment.py", line 832, in handle_exception
    reraise(*rewrite_traceback_stack(source=source))
  File "/Users/ilja/.virtualenvs/flask-megatut-FibpGiLO/lib/python3.7/site-packages/jinja2/_compat.py", line 28, in reraise
    raise value.with_traceback(tb)
  File "/Users/ilja/Dropbox/flask-megatut/app/templates/view_db.html", line 1, in top-level template code
    {% extends "base.html" %}
  File "/Users/ilja/Dropbox/flask-megatut/app/templates/base.html", line 45, in top-level template code
    {% block content %}{% endblock %}
  File "/Users/ilja/Dropbox/flask-megatut/app/templates/view_db.html", line 5, in block "content"
    <p><img src="{{ user.avatar(128) }}"></p>
  File "/Users/ilja/.virtualenvs/flask-megatut-FibpGiLO/lib/python3.7/site-packages/jinja2/environment.py", line 471, in getattr
    return getattr(obj, attribute)
jinja2.exceptions.UndefinedError: 'user' is undefined
2020-06-23 10:16:12,569 INFO: Microblog startup [in /Users/ilja/Dropbox/flask-megatut/app/__init__.py:76]
2020-06-23 10:20:54,706 INFO: Microblog startup [in /Users/ilja/Dropbox/flask-megatut/app/__init__.py:76]
2020-06-23 10:24:05,004 INFO: Microblog startup [in /Users/ilja/Dropbox/flask-megatut/app/__init__.py:76]
2020-06-23 10:26:12,417 INFO: Microblog startup [in /Users/ilja/Dropbox/flask-megatut/app/__init__.py:76]
2020-06-23 10:26:15,183 ERROR: Exception on /view_db [GET] [in /Users/ilja/.virtualenvs/flask-megatut-FibpGiLO/lib/python3.7/site-packages/flask/app.py:1892]
Traceback (most recent call last):
  File "/Users/ilja/.virtualenvs/flask-megatut-FibpGiLO/lib/python3.7/site-packages/flask/app.py", line 2447, in wsgi_app
    response = self.full_dispatch_request()
  File "/Users/ilja/.virtualenvs/flask-megatut-FibpGiLO/lib/python3.7/site-packages/flask/app.py", line 1952, in full_dispatch_request
    rv = self.handle_user_exception(e)
  File "/Users/ilja/.virtualenvs/flask-megatut-FibpGiLO/lib/python3.7/site-packages/flask/app.py", line 1821, in handle_user_exception
    reraise(exc_type, exc_value, tb)
  File "/Users/ilja/.virtualenvs/flask-megatut-FibpGiLO/lib/python3.7/site-packages/flask/_compat.py", line 39, in reraise
    raise value
  File "/Users/ilja/.virtualenvs/flask-megatut-FibpGiLO/lib/python3.7/site-packages/flask/app.py", line 1950, in full_dispatch_request
    rv = self.dispatch_request()
  File "/Users/ilja/.virtualenvs/flask-megatut-FibpGiLO/lib/python3.7/site-packages/flask/app.py", line 1936, in dispatch_request
    return self.view_functions[rule.endpoint](**req.view_args)
  File "/Users/ilja/.virtualenvs/flask-megatut-FibpGiLO/lib/python3.7/site-packages/flask_login/utils.py", line 272, in decorated_view
    return func(*args, **kwargs)
  File "/Users/ilja/Dropbox/flask-megatut/app/routes.py", line 264, in view_db
    print(c, ck, user.ck)
AttributeError: 'User' object has no attribute 'ck'
2020-06-23 10:26:39,321 INFO: Microblog startup [in /Users/ilja/Dropbox/flask-megatut/app/__init__.py:76]
2020-06-23 10:27:20,398 INFO: Microblog startup [in /Users/ilja/Dropbox/flask-megatut/app/__init__.py:76]
